
<robot name="classb_car" xmlns:xacro="http://www.ros.org/wiki/xacro">

    <xacro:property name="PI" value="3.141"/>

    <xacro:property name="base_length" value="2.695"/>
    <xacro:property name="base_width" value="0.68"/>
    <xacro:property name="base_height" value="1.370"/>
    <xacro:property name="base_collision_height" value="0.875"/>
    <xacro:property name="base_mass" value="956"/>
    <xacro:property name="base_mass_ixx" value="343"/>
    <xacro:property name="base_mass_iyy" value="728"/>
    <xacro:property name="base_mass_izz" value="772"/>

    <xacro:property name="rear_tyre_x" value="0.945"/>
    <xacro:property name="rear_tyre_y" value="0.642"/>
    <xacro:property name="rear_tyre_r" value="0.3"/>
    <xacro:property name="rear_tyre_length" value="0.165"/>
    <xacro:property name="rear_tyre_mass" value="20"/>
    <xacro:property name="rear_tyre_mass_ixx" value="0.5"/>
    <xacro:property name="rear_tyre_mass_iyy" value="0.9"/>
    <xacro:property name="rear_tyre_mass_izz" value="0.5"/> 

    <xacro:property name="front_tyre_x" value="0.923"/>
    <xacro:property name="front_tyre_y" value="0.642"/>
    <xacro:property name="front_tyre_r" value="0.3"/>
    <xacro:property name="front_tyre_length" value="0.165"/>
    <xacro:property name="front_tyre_mass" value="20"/>
    <xacro:property name="front_tyre_mass_ixx" value="0.5"/>
    <xacro:property name="front_tyre_mass_iyy" value="0.9"/>
    <xacro:property name="front_tyre_mass_izz" value="0.5"/>  

    <xacro:property name="str_angle" value="0.6"/>    
    <xacro:property name="str_length" value="0.01"/>
    <xacro:property name="str_radius" value="0.1"/>
    <xacro:property name="str_mass" value="5"/>
    <xacro:property name="str_mass_ixx" value="0.012"/>
    <xacro:property name="str_mass_iyy" value="0.025"/>
    <xacro:property name="str_mass_izz" value="0.012"/>

    <!--base_link part-->
    <link name="base_link">
      <visual>
        <geometry>
          <box size="${base_length} ${base_width} ${base_height}"/>
        </geometry>
        <material name="yellow">
          <color rgba="0.5 0.7 0.2 0.8" />
        </material>
        <origin xyz="0 0 ${base_collision_height}" rpy="0 0 0"/>
      </visual>
      <collision>
        <origin xyz="0 0 ${base_collision_height}" rpy="0 0 0"/>  
        <geometry>
          <box size="${base_length} ${base_width} ${base_height}"/>
        </geometry>
      </collision>
    </link>
    <link name="main_mass" type="fixed">
      <inertial>
        <origin xyz="0 0 0" rpy="0 0 0"/>
        <mass value="${base_mass}"/>
        <inertia
          ixx="${base_mass_ixx}"  ixy="0.000000"  ixz="0.000000"
          iyy="${base_mass_iyy}"  iyz="0.000000"
          izz="${base_mass_izz}"/>
        </inertial>
    </link>
    <joint name="inertial_joint" type="fixed">
      <parent link="base_link"/>
      <child link="main_mass"/>
      <origin xyz="0 0 0" rpy="0 0 0"/>
    </joint>

    <!--rear_right_wheel part-->
    <link name="rear_right_wheel_link">
        <visual>
          <geometry>
            <cylinder length="${rear_tyre_length}" radius="${rear_tyre_r}"/>
          </geometry>
          <material name="red">
            <color rgba="0.8 0.1 0.2 0.9" />
          </material>
          <origin xyz="0 0 0" rpy="${PI/2} 0 0"/>
        </visual>
        <collision>
            <origin xyz="0 0 0" rpy="${PI/2} 0 0"/>
            <geometry>
                <cylinder length="${rear_tyre_length}" radius="${rear_tyre_r}"/>
            </geometry>
        </collision>
        <inertial>
          <origin xyz="0 0 0" rpy="0 0 0"/>
          <mass value="${rear_tyre_mass}"/>
          <inertia
            ixx="${rear_tyre_mass_ixx}"  ixy="0.000000"  ixz="0.000000"
            iyy="${rear_tyre_mass_iyy}"  iyz="0.000000"
            izz="${rear_tyre_mass_izz}"/>
        </inertial>
    </link>
    <joint name="rear_right_wheel_joint" type="continuous">
        <parent link="base_link"/>
        <child link="rear_right_wheel_link"/>
        <origin xyz="${-rear_tyre_x} ${-rear_tyre_y} ${rear_tyre_r}" rpy="0 0 0"/>
        <axis xyz="0 1 0"/>
        <dynamics damping="0.1"/>
        <joint_properties damping="0.0" friction="0.0" />
    </joint>
    
    <!--rear_left_wheel part-->
    <link name="rear_left_wheel_link">
      <collision>
        <origin xyz="0 0 0" rpy="${PI/2} 0 0"/>
        <geometry>
          <cylinder length="${rear_tyre_length}" radius="${rear_tyre_r}"/>
        </geometry>
      </collision>
      <visual>
        <origin xyz="0 0 0" rpy="${PI/2} 0 0"/>
        <geometry>
          <cylinder length="${rear_tyre_length}" radius="${rear_tyre_r}"/>
        </geometry>
      </visual>
      <inertial>
        <origin xyz="0 0 0" rpy="0 0 0"/>
        <mass value="${rear_tyre_mass}"/>
        <inertia
          ixx="${rear_tyre_mass_ixx}"  ixy="0.000000"  ixz="0.000000"
          iyy="${rear_tyre_mass_iyy}"  iyz="0.000000"
          izz="${rear_tyre_mass_izz}"/>
      </inertial>
    </link>
    <joint name="rear_left_wheel_joint" type="continuous">
      <parent link="base_link"/>
      <child link="rear_left_wheel_link"/>
      <origin xyz="${-rear_tyre_x} ${rear_tyre_y} ${rear_tyre_r}" rpy="0 0 0"/>
      <axis xyz="0 1 0"/>
      <joint_properties damping="0.0" friction="0.0" />
      <dynamics damping="0.1"/>
    </joint> 

    <!--Front Right Steering part-->
    <link name="front_right_steering_link">
      <visual>
        <origin xyz="0 0 0" rpy="${PI/2} 0 0"/>
        <geometry>
          <cylinder length="${str_length}" radius="${str_radius}"/>
        </geometry>
      </visual>
      <inertial>
        <origin xyz="0 0 0" rpy="0 0 0"/>
        <mass value="${str_mass}"/>
        <inertia
        ixx="${str_mass_ixx}"  ixy="0.000000"  ixz="0.000000"
        iyy="${str_mass_iyy}"  iyz="0.000000"
        izz="${str_mass_izz}"/>
      </inertial>
    </link>
    <joint name="front_right_steering_joint" type="revolute">
      <parent link="base_link"/>
      <child link="front_right_steering_link"/>
      <origin xyz="${front_tyre_x} ${-front_tyre_y} ${front_tyre_r}" rpy="0 0 0"/>
      <axis xyz="0 0 1"/>
      <limit lower="${-str_angle}" upper="${str_angle}" effort="1000000.0" velocity="10000.0"/>
      <dynamics damping="10.0" friction="0.0"/>
    </joint>

    <!--Front Right Wheel part-->
    <link name="front_right_wheel_link">
      <collision>
        <origin xyz="0 0 0" rpy="${PI/2} 0 0"/>
        <geometry>
          <cylinder length="${front_tyre_length}" radius="${front_tyre_r}"/>
        </geometry>
      </collision>
      <visual>
        <origin xyz="0 0 0" rpy="${PI/2} 0 0"/>
        <geometry>
          <!--<mesh filename="package://car_model/meshes/wheel.dae"/>-->
          <cylinder length="${front_tyre_length}" radius="${front_tyre_r}"/>
        </geometry>
        <material name="red">
          <color rgba="0.9 0.2 0.2 0.5" />
        </material>
      </visual>
      <inertial>
        <origin xyz="0 0 0" rpy="0 0 0"/>
        <mass value="${front_tyre_mass}"/>
        <inertia
          ixx="${front_tyre_mass_ixx}"  ixy="0.000000"  ixz="0.000000"
          iyy="${front_tyre_mass_iyy}"  iyz="0.000000"
          izz="${front_tyre_mass_izz}"/>
      </inertial>
    </link>
    <joint name="front_right_wheel_joint" type="continuous">
      <parent link="front_right_steering_link"/>
      <child link="front_right_wheel_link"/>
      <origin xyz="0 0 0" rpy="0 0 0"/>
      <axis xyz="0 1 0"/>
      <limit effort="1000000" velocity="10000" />
      <joint_properties damping="0.0" friction="0.0" />
      <dynamics damping="0.1"/>
    </joint>

    <!--Front Left Steering-->
    <link name="front_left_steering_link">
      <visual>
        <origin xyz="0 0 0" rpy="${PI/2} 0 0"/>
        <geometry>
          <cylinder length="${str_length}" radius="${str_radius}"/>
        </geometry>
      </visual>
      <inertial>
        <origin xyz="0 0 0" rpy="0 0 0"/>
        <mass value="${str_mass}"/>
        <inertia
        ixx="${str_mass_ixx}"  ixy="0.000000"  ixz="0.000000"
        iyy="${str_mass_iyy}"  iyz="0.000000"
        izz="${str_mass_izz}"/>
      </inertial>
    </link>
    <joint name="front_left_steering_joint" type="revolute">
      <parent link="base_link"/>
      <child link="front_left_steering_link"/>
      <origin xyz="${front_tyre_x} ${front_tyre_y} ${front_tyre_r}" rpy="0 0 0"/>
      <axis xyz="0 0 1"/>
      <limit lower="${-str_angle}" upper="${str_angle}" effort="1000000.0" velocity="10000.0"/>
      <dynamics damping="10.0" friction="0.0"/>
    </joint>

    <!--Front Left Wheel-->
    <link name="front_left_wheel_link">
      <collision>
        <origin xyz="0 0 0" rpy="${PI/2} 0 0"/>
        <geometry>
          <cylinder length="${front_tyre_length}" radius="${front_tyre_r}"/>
        </geometry>
      </collision>
      <visual>
        <origin xyz="0 0 0" rpy="${PI/2} 0 0"/>
        <geometry>
          <!--<mesh filename="package://car_model/meshes/wheel.dae"/>-->
          <cylinder length="${front_tyre_length}" radius="${front_tyre_r}"/>
        </geometry>
        <material name="red">
          <color rgba="0.9 0.2 0.2 0.5" />
        </material>  
      </visual>
      <inertial>
        <origin xyz="0 0 0" rpy="0 0 0"/>
        <mass value="${front_tyre_mass}"/>
        <inertia
          ixx="${front_tyre_mass_ixx}"  ixy="0.000000"  ixz="0.000000"
          iyy="${front_tyre_mass_iyy}"  iyz="0.000000"
          izz="${front_tyre_mass_izz}"/>
      </inertial>
    </link>
    <joint name="front_left_wheel_joint" type="continuous">
      <parent link="front_left_steering_link"/>
      <child link="front_left_wheel_link"/>
      <origin xyz="0 0 0" rpy="0 0 0"/>
      <axis xyz="0 1 0"/>
      <limit effort="1000000" velocity="10000" />
      <joint_properties damping="0.0" friction="0.0" />
      <dynamics damping="0.1"/>
    </joint>

    <gazebo reference="base_link">
        <material>Gazebo/Black</material>
    </gazebo>

    <gazebo>
            <plugin name='diff_drive' filename='libgazebo_ros_diff_drive.so'>
                <ros>
                    <namespace>/</namespace>
                    <remapping>cmd_vel:=cmd_vel</remapping>
                    <remapping>odom:=odom</remapping>
                </ros>
                <update_rate>30</update_rate>
                <!-- wheels -->
                <left_joint>left_wheel_joint</left_joint>
                <right_joint>right_wheel_joint</right_joint>
                <!-- kinematics -->
                <wheel_separation>0.2</wheel_separation>
                <wheel_diameter>0.064</wheel_diameter>
                <!-- limits -->
                <max_wheel_torque>20</max_wheel_torque>
                <max_wheel_acceleration>1.0</max_wheel_acceleration>
                <!-- output -->
                <publish_odom>true</publish_odom>
                <publish_odom_tf>true</publish_odom_tf>
                <publish_wheel_tf>true</publish_wheel_tf>

                <odometry_frame>odom</odometry_frame>
                <robot_base_frame>base_footprint</robot_base_frame>
            </plugin>
    </gazebo>

</robot>